Workbook

Sheet README
A1: Washington, D.C. streetcar lines, 1862–1962
A3: Sheets
A4: Chronology: 176 dated events (charters, openings, extensions, power changes, closures), sorted by year and keyed to Line IDs.
A5: Route Numbers 1936-62: every Capital Transit / D.C. Transit streetcar route number with termini, the 1946 street-by-street routing (Tundria) where known, and end dates. Routes 40/42 corrected in version 5.
A6: Track Ways: the network as a node-and-way model, split into stretches of physical track. Each stretch is one way tagged railway=tram with start_date and end_date; the lines that run over it are route relations (type=route, route=tram), whose tags are in the Lines sheet. Shared stretches are listed first. The same model is exported as dc_streetcars_OHM_draft.osm.
A7: Relations: each line is a type=chronology relation listing its dated route relations in order. Each dated route (type=route, route=tram) covers a period in which the line used the same set of ways, with the same operator and motive power (railway:traction), and carries its own start_date and end_date. A way records only when the track itself existed, so one way can belong to different routes in different periods.
A8: Track Nodes: tagged nodes in the track network: railway=railway_crossing where two tracks cross at grade (dated to the years both tracks existed) and railway=switch where tracks branch.
A9: 1905 Franchise Laws: acts of Congress and charters for lines that were actually built, with the authorized route trimmed to the portion that was built, and the matching Line ID.
A10: Research Notes: source conflicts, corrections made in this version, unreliable sources, gaps, and primary sources worth mining next.
A11: Lines: one row per line, branch or extension, with streets, company, motive power, opening and closing dates, and 1936+ route numbers. The four right-hand columns give the length of track drawn for the line, how much of it is shared, the lines it shares track with, and its route relation tags in OHM form. The numeric 'First year' and 'Year service ended' columns are there for time-slider mapping.
A12: Summary: counts of lines opened and ended by decade (live formulas from the Lines sheet).
A13: CTC Route Table: the chicagorailfan.com line-by-line table (horse, cable and electric start years plus bus conversion date), with duplicates removed.
... A23: Compiled Sept 24, 2026. Version 7 is limited to lines, extensions and events that were actually built: unbuilt charters, proposals and routes have been removed. Version 5 added findings from reviewing the 1880, 1891, 1910, 1924, 1942, 1946 and 1958 maps: corrected route termini, three new line rows (L56–L58), and the Rand McNally map series.

Sheet Summary
A1: Lines by decade (formulas read the Lines sheet)
A3: Decade start | B3: Lines opened | C3: Lines ended | D3: Net change
A4: 1860 | B4: =COUNTIFS(Lines!$H$2:$H$66,">="&A4,Lines!$H$2:$H$66,"<"&A4+10) -> 5 | C4: =COUNTIFS(Lines!$N$2:$N$66,">="&A4,Lines!$N$2:$N$66,"<"&A4+10) -> 0 | D4: =B4-C4 -> 5
A5: 1870 | B5: =COUNTIFS(Lines!$H$2:$H$66,">="&A5,Lines!$H$2:$H$66,"<"&A5+10) -> 11 | C5: =COUNTIFS(Lines!$N$2:$N$66,">="&A5,Lines!$N$2:$N$66,"<"&A5+10) -> 0 | D5: =B5-C5 -> 11
A6: 1880 | B6: =COUNTIFS(Lines!$H$2:$H$66,">="&A6,Lines!$H$2:$H$66,"<"&A6+10) -> 3 | C6: =COUNTIFS(Lines!$N$2:$N$66,">="&A6,Lines!$N$2:$N$66,"<"&A6+10) -> 0 | D6: =B6-C6 -> 3
A7: 1890 | B7: =COUNTIFS(Lines!$H$2:$H$66,">="&A7,Lines!$H$2:$H$66,"<"&A7+10) -> 24 | C7: =COUNTIFS(Lines!$N$2:$N$66,">="&A7,Lines!$N$2:$N$66,"<"&A7+10) -> 2 | D7: =B7-C7 -> 22
A8: 1900 | B8: =COUNTIFS(Lines!$H$2:$H$66,">="&A8,Lines!$H$2:$H$66,"<"&A8+10) -> 12 | C8: =COUNTIFS(Lines!$N$2:$N$66,">="&A8,Lines!$N$2:$N$66,"<"&A8+10) -> 1 | D8: =B8-C8 -> 11
A9: 1910 | B9: =COUNTIFS(Lines!$H$2:$H$66,">="&A9,Lines!$H$2:$H$66,"<"&A9+10) -> 5 | C9: =COUNTIFS(Lines!$N$2:$N$66,">="&A9,Lines!$N$2:$N$66,"<"&A9+10) -> 0 | D9: =B9-C9 -> 5
A10: 1920 | B10: =COUNTIFS(Lines!$H$2:$H$66,">="&A10,Lines!$H$2:$H$66,"<"&A10+10) -> 1 | C10: =COUNTIFS(Lines!$N$2:$N$66,">="&A10,Lines!$N$2:$N$66,"<"&A10+10) -> 10 | D10: =B10-C10 -> -9
A11: 1930 | B11: =COUNTIFS(Lines!$H$2:$H$66,">="&A11,Lines!$H$2:$H$66,"<"&A11+10) -> 1 | C11: =COUNTIFS(Lines!$N$2:$N$66,">="&A11,Lines!$N$2:$N$66,"<"&A11+10) -> 14 | D11: =B11-C11 -> -13
A12: 1940 | B12: =COUNTIFS(Lines!$H$2:$H$66,">="&A12,Lines!$H$2:$H$66,"<"&A12+10) -> 0 | C12: =COUNTIFS(Lines!$N$2:$N$66,">="&A12,Lines!$N$2:$N$66,"<"&A12+10) -> 5 | D12: =B12-C12 -> -5
A13: 1950 | B13: =COUNTIFS(Lines!$H$2:$H$66,">="&A13,Lines!$H$2:$H$66,"<"&A13+10) -> 0 | C13: =COUNTIFS(Lines!$N$2:$N$66,">="&A13,Lines!$N$2:$N$66,"<"&A13+10) -> 4 | D13: =B13-C13 -> -4
A14: 1960 | B14: =COUNTIFS(Lines!$H$2:$H$66,">="&A14,Lines!$H$2:$H$66,"<"&A14+10) -> 0 | C14: =COUNTIFS(Lines!$N$2:$N$66,">="&A14,Lines!$N$2:$N$66,"<"&A14+10) -> 21 | D14: =B14-C14 -> -21
A15: Total | B15: =SUM(B4:B14) -> 62 | C15: =SUM(C4:C14) -> 57 | D15: =B15-C15 -> 5
A17: Lines with no end year recorded | C17: =COUNTA(Lines!$A$2:$A$66)-COUNT(Lines!$N$2:$N$66) -> 8
A18: Total rows in Lines sheet | C18: =COUNTA(Lines!$A$2:$A$66) -> 65
A20: Counts are by segment/row, not by company; a line split into branches counts once per branch.

Sheet Lines
A1: ID | B1: Line / corridor | C1: Streets & termini (as described in sources) | D1: Jurisdiction | E1: Original company | F1: Later operators | G1: Motive power history | H1: First year of rail service | I1: Horse cars from | J1: Cable from | K1: Electric from | L1: Capital Transit route no(s). (1936+) | M1: Streetcar service ended | N1: Year service ended | O1: Replaced by | P1: Notes | Q1: Sources | R1: Track drawn (km) | S1: Of which shared (km) | T1: Shares track with | U1: Chronology and dated routes (OHM)
A2: L01 | B2: Pennsylvania Avenue line (Georgetown–Navy Yard) | C2: M St NW (Georgetown) – Pennsylvania Ave NW/SE – Navy Yard; extended 1895 from 32nd St to 36th & M St (Georgetown Car Barn); extended on Pennsylvania Ave SE from 8th St to 17th St SE in 1901, later to Barney Circle | D2: DC | E2: Washington & Georgetown Railroad | F2: Capital Traction (1895); Capital Transit (1933); D.C. Transit (1956) | G2: Horse → cable (1892) → horse again after Sept 1897 powerhouse fire → underground conduit electric (1898) | H2: 1862 | I2: 1862 | J2: 1892 | K2: 1898 | L2: 30 (Wisconsin Ave–Pennsylvania Ave SE); 54 (14th St–Pennsylvania Ave to Navy Yard) | M2: Route 30: Jan 3, 1960; Route 54: Jan 28, 1962 | N2: 1962 | O2: Bus routes 30s / 54 | P2: Capitol–White House July 29, 1862; Washington Circle Aug 12; Georgetown Aug 18; Navy Yard Oct 2. Electrified Apr 20, 1898. West End loop 1901. West End loops: see L56. Map: westbound cars used a Wisconsin Ave, Prospect St and 34th St loop in 1946 (Tundria), and the line used M St and 26th St between 1875 and 1916 (1880 map). 1912 map (audit): the 1901 extension ended in a loop around the block at 15th St SE. | Q2: WP; MPD; CRF | R2: 11.73 | S2: 2.74 | T2: L02, L05, L18, L22, L32, L34, L36, L56 | U2: type=chronology name=Pennsylvania Avenue line (Georgetown–Navy Yard) network=Washington, D.C. streetcars operator=Washington & Georgetown Railroad start_date=1862 end_date=1962 ref:streetcar_project=L01 ref=30;54 description=Later operators: Capital Traction (1895); Capital Transit (1933); D.C. Transit (1956) source=WP; MPD; CRF Dated route relations in this chronology: 1862–1875: 24 ways; operator=Washington & Georgetown Railroad; railway:traction=horse 1875–1892: 25 ways; operator=Washington & Georgetown Railroad; railway:traction=horse 1892–1895: 25 ways; operator=Washington & Georgetown Railroad; railway:traction=cable 1895–1898: 28 ways; operator=Capital Traction; railway:traction=cable 1898–1901: 28 ways; operator=Capital Traction; railway:traction=electric 1901–1916: 30 ways; operator=Capital Traction; railway:traction=electric 1916–1934: 29 ways; operator=Capital Traction; railway:traction=electric 1934–1936: 29 ways; operator=Capital Transit; railway:traction=electric 1936–1956: 31 ways; operator=Capital Transit; railway:traction=electric 1956–1960: 31 ways; operator=D.C. Transit; railway:traction=electric 1960–1962: 29 ways; operator=D.C. Transit; railway:traction=electric
A3: L02 | B3: 7th Street line | C3: 7th St NW/SW from Boundary St (Florida Ave) to the Potomac wharves; extended to the Arsenal (Fort McNair) in 1875; ran along M St SW to 7th St | D3: DC | E3: Washington & Georgetown Railroad | F3: Capital Traction (1895); Capital Transit; D.C. Transit | G3: Horse → cable (May 12, 1890, DC's first cable line) → horse after 1897 fire → electric conduit (1898) | H3: 1862 | I3: 1862 | J3: 1890 | K3: 1898 | L3: 70 (7th St–Georgia Ave); 76, 78 (to wharves, 1936) | M3: Jan 3, 1960 | N3: 1960 | O3: Bus route 70 | P3: Opened Nov 15, 1862. DC's first cable line (Apr 12, 1890 per Wikipedia; May 12 per NRHP). Electrified May 26, 1898. Cable powerhouse at P & Water Sts SW. 1912 map: south of M St the line ran along the old Water St beside the Washington Channel to P St and the Arsenal gate (the modern Maine Ave and Wharf streets are drawn differently, so this stretch is drawn straight). | Q3: WP; MPD; CRF; GDC | R3: 7.23 | S3: 1.94 | T3: L01, L08, L18, L22, L34 | U3: type=chronology name=7th Street line network=Washington, D.C. streetcars operator=Washington & Georgetown Railroad start_date=1862 end_date=1960 ref:streetcar_project=L02 ref=70;76;78 description=Later operators: Capital Traction (1895); Capital Transit; D.C. Transit source=WP; MPD; CRF; GDC Dated route relations in this chronology: 1862–1875: 15 ways; operator=Washington & Georgetown Railroad; railway:traction=horse 1875–1890: 17 ways; operator=Washington & Georgetown Railroad; railway:traction=horse 1890–1895: 17 ways; operator=Washington & Georgetown Railroad; railway:traction=cable 1895–1898: 17 ways; operator=Capital Traction; railway:traction=cable 1898–1934: 17 ways; operator=Capital Traction; railway:traction=electric 1934–1941: 17 ways; operator=Capital Transit; railway:traction=electric 1941–1956: 27 ways; operator=Capital Transit; railway:traction=electric 1956–1960: 27 ways; operator=D.C. Transit; railway:traction=electric
A4: L03 | B4: 14th Street line | C4: 14th St NW from Boundary St to the Treasury (15th St & New York Ave); extended up the hill to Park Rd (Mount Pleasant) c.1892–95; extended to Colorado Ave 1906–07 (Decatur St car barn); Colorado Ave terminal by 1937 | D4: DC | E4: Washington & Georgetown Railroad | F4: Capital Traction (1895); Capital Transit; D.C. Transit | G4: Horse → cable (1892; CRF lists 1895) → electric conduit (1898) | H4: 1862 | I4: 1862 | J4: 1892 | K4: 1898 | L4: 50 (to Bureau of Engraving); 52; 54 (to Navy Yard) | M4: Jan 28, 1962 (last line in DC) | N4: 1962 | O4: Bus routes 50s | P4: Electrified Feb 27, 1898. First PCC cars Aug 1937. Last scheduled run left 14th & Colorado 2:17 am, Jan 28, 1962. | Q4: WP; MPD; CRF | R4: 6.38 | S4: 0.16 | T4: L15 | U4: type=chronology name=14th Street line network=Washington, D.C. streetcars operator=Washington & Georgetown Railroad start_date=1862 end_date=1962 ref:streetcar_project=L03 ref=50;52;54 description=Later operators: Capital Traction (1895); Capital Transit; D.C. Transit source=WP; MPD; CRF Dated route relations in this chronology: 1862–1892: 4 ways; operator=Washington & Georgetown Railroad; railway:traction=horse 1892–1895: 5 ways; operator=Washington & Georgetown Railroad; railway:traction=cable 1895–1898: 5 ways; operator=Capital Traction; railway:traction=cable 1898–1906: 5 ways; operator=Capital Traction; railway:traction=electric 1906–1907: 6 ways; operator=Capital Traction; railway:traction=electric 1907–1934: 7 ways; operator=Capital Traction; railway:traction=electric 1934–1956: 7 ways; operator=Capital Transit; railway:traction=electric 1956–1962: 7 ways; operator=D.C. Transit; railway:traction=electric
A5: L04 | B5: Georgetown–B&O Depot (Capitol Hill) line | C5: Georgetown to the B&O depot at New Jersey Ave & C St NW; later Mount Pleasant–B&O Depot via Pennsylvania Ave and 14th St (cable era) | D5: DC | E5: Washington & Georgetown Railroad | F5: Capital Traction (1895) | G5: Horse → cable → electric | H5: 1862 | I5: 1862 | J5: 1892 | K5: 1898 | L5: — | M5: Absorbed into other routes (depot razed after 1907) | O5: — | P5: One of four W&G services in 1863 (21 cars). | Q5: MPD | R5: 0.42 | S5: 0.4 | T5: L22, L55, L58 | U5: type=chronology name=Georgetown–B&O Depot (Capitol Hill) line network=Washington, D.C. streetcars operator=Washington & Georgetown Railroad start_date=1862 end_date=1908 ref:streetcar_project=L04 end_date:edtf=1908~ description=Later operators: Capital Traction (1895) source=MPD Dated route relations in this chronology: 1862–1892: 6 ways; operator=Washington & Georgetown Railroad; railway:traction=horse 1892–1895: 6 ways; operator=Washington & Georgetown Railroad; railway:traction=cable 1895–1898: 6 ways; operator=Capital Traction; railway:traction=cable 1898–1908: 6 ways; operator=Capital Traction; railway:traction=electric
A6: L05 | B6: Metropolitan main line (Capitol–War Dept; later F St/D St line) | C6: Charter route (1864): A St & New Jersey Ave via D, C, Indiana Ave, 5th, F and 14th Sts. As built (Jan 1865): Capitol to 14th & I Sts NW, plus H St NW from Massachusetts Ave to 17th St | D6: DC | E6: Metropolitan Railroad | F6: Washington Traction & Electric (1899); WRECo (1902); Capital Transit; D.C. Transit | G6: Horse → electric conduit (1896) | H6: 1865 | I6: 1865 | J6: — | K6: 1896 | L6: 42 (Mt. Pleasant); D6 bus later | M6: Dec 3, 1961 | N6: 1961 | O6: Bus D6 / 42 | P6: CRF dates horse service 1865. 1912 map: a link ran along Indiana Ave from D St to C St at 1st St NW. | Q6: WP; MPD; CRF | R6: 5.29 | S6: 0.16 | T6: L01 | U6: type=chronology name=Metropolitan main line (Capitol–War Dept; later F St/D St line) network=Washington, D.C. streetcars operator=Metropolitan Railroad start_date=1865 end_date=1961 ref:streetcar_project=L05 ref=42 description=Later operators: Washington Traction & Electric (1899); WRECo (1902); Capital Transit; D.C. Transit source=WP; MPD; CRF Dated route relations in this chronology: 1865–1896: 22 ways; operator=Metropolitan Railroad; railway:traction=horse 1896–1902: 22 ways; operator=Metropolitan Railroad; railway:traction=electric 1902–1934: 22 ways; operator=Washington Railway & Electric; railway:traction=electric 1934–1956: 22 ways; operator=Capital Transit; railway:traction=electric 1956–1961: 22 ways; operator=D.C. Transit; railway:traction=electric
A7: L06 | B7: 9th Street line | C7: 9th St NW north from M St to Boundary St, joining the Boundary & Silver Spring line | D7: DC | E7: Metropolitan Railroad | F7: WRECo (1902); Capital Transit | G7: Horse (1872) → first underground-conduit electric line in DC (1895) | H7: 1872 | I7: 1872 | J7: — | K7: 1895 | L7: — | M7: 1933 (NRHP) or 1936 (Ghosts of DC) | N7: 1933 | O7: Buses | P7: Sources disagree on the conversion year: NRHP says 1933 with the rebuilding of 9th St; Ghosts of DC says cars were pulled in 1936. Map: 9th St track continued south to Pennsylvania Ave (1912 map); route 40 ran via 9th St, Pennsylvania Ave and C St NW in 1946. 1912 map: north of Florida Ave the 9th St track curved northwest to join the 11th St line near Kenyon St (date of this curve not documented). | Q7: MPD; GDC | R7: 4.01 | S7: 0.15 | T7: L15, L31 | U7: type=chronology name=9th Street line network=Washington, D.C. streetcars operator=Metropolitan Railroad start_date=1872 end_date=1961 ref:streetcar_project=L06 description=Later operators: WRECo (1902); Capital Transit source=MPD; GDC Dated route relations in this chronology: 1872–1895: 11 ways; operator=Metropolitan Railroad; railway:traction=horse 1895–1902: 11 ways; operator=Metropolitan Railroad; railway:traction=electric 1902–1933: 11 ways; operator=Washington Railway & Electric; railway:traction=electric 1936–1961: 1 ways; operator=Capital Transit; railway:traction=electric
A8: L07 | B8: P Street / Georgetown line | C8: P St NW west from Dupont Circle to Georgetown (36th & Prospect St), built under the Union Railroad charter; completed 1880 | D8: DC | E8: Metropolitan Railroad (Union Railroad charter) | F8: WRECo; Capital Transit | G8: Horse → battery trials (1891–93) → electric conduit (1896) | H8: 1873 | I8: 1873 | J8: — | K8: 1896 | L8: — (bus G2) | M8: June 16, 1935 | N8: 1935 | O8: Bus G2 | P8: Union RR absorbed Aug–Nov 1872 without authority. Georgetown loop on P, 36th, Prospect and 35th Sts authorized 1895. Rails remain on O & P Sts between 33rd and 35th Sts NW. Map: the Georgetown P and O St loop west of Wisconsin Ave stayed in use for Cabin John cars until 1960 (1958 trackage map). 1912 map: a loop east of Wisconsin Ave ran via P St, 28th St and Dumbarton St. 1912 map (Georgetown): cars ran out P St to 36th St, down to the car barn at Prospect St, along Prospect and up 35th St, then east on O St across Wisconsin Ave into Dumbarton St and back up 28th St. The original 1873 loop used P, 35th, O and 33rd Sts; the O St and P St loop west of Wisconsin was later the Cabin John cars' terminal (1935–60, from the 1958 trackage map). | Q8: WP; MPD; CRF | R8: 4.57 | S8: 1.74 | T8: L36, L39 | U8: type=chronology name=P Street / Georgetown line network=Washington, D.C. streetcars operator=Metropolitan Railroad (Union Railroad charter) start_date=1873 end_date=1935 ref:streetcar_project=L07 description=Later operators: WRECo; Capital Transit source=WP; MPD; CRF Dated route relations in this chronology: 1873–1896: 10 ways; operator=Metropolitan Railroad; railway:traction=horse 1896–1902: 10 ways; operator=Metropolitan Railroad; railway:traction=electric 1902–1934: 10 ways; operator=Washington Railway & Electric; railway:traction=electric 1934–1935: 10 ways; operator=Capital Transit; railway:traction=electric
A9: L08 | B9: 4th Street NW/SW line | C9: 4½ St (now 4th St) SW from Missouri Ave to P St SW / Arsenal; reached via unauthorized tracks on B St, 6th St and Missouri Ave | D9: DC | E9: Metropolitan Railroad | F9: WRECo; Capital Transit | G9: Horse → electric (1895) | H9: 1872 | I9: 1872 | J9: — | K9: 1895 | L9: — (buses V2/M2) | M9: 1930s | N9: 1935 | O9: Bus M2 | P9: CRF gives '1930s' only; end year approximate. Map: reached 4½ St via 9th St, B St (Constitution Ave), 6th St and Missouri Ave (1880 and 1912 maps). 1912 map: 4½ St is today's 4th St SW; the line ran down Missouri Ave from 6th & B Sts onto it. | Q9: WP; CRF | R9: 2.72 | S9: 2.04 | T9: L02, L18 | U9: type=chronology name=4th Street NW/SW line network=Washington, D.C. streetcars operator=Metropolitan Railroad start_date=1872 end_date=1935 ref:streetcar_project=L08 description=Later operators: WRECo; Capital Transit source=WP; CRF Dated route relations in this chronology: 1872–1895: 7 ways; operator=Metropolitan Railroad; railway:traction=horse 1895–1902: 7 ways; operator=Metropolitan Railroad; railway:traction=electric 1902–1934: 7 ways; operator=Washington Railway & Electric; railway:traction=electric 1934–1935: 7 ways; operator=Capital Transit; railway:traction=electric
A10: L09 | B10: East Capitol Street line | C10: East Capitol St to 9th St (by 1888); extended 1896 to the East Capitol St car barn / Lincoln Park loop (1400 East Capitol St) | D10: DC | E10: Metropolitan Railroad | F10: WRECo; Capital Transit; D.C. Transit | G10: Horse → electric conduit (1896) | H10: 1872 | I10: 1872 | J10: — | K10: 1896 | L10: 40 (Lincoln Park); 96 bus later | M10: Jan 28, 1962 | N10: 1962 | O10: Bus 96 | P10: One of the last two car barns in service (Lincoln Park). Map: reached East Capitol St via C St, Delaware Ave, B St (Constitution Ave) and 1st St NE (1880 map). 1912 map: tracks ran around both sides of Lincoln Park and ended in a loop around the block east of the park. | Q10: WP; MPD; CRF | R10: 3.65 | S10: 0.5 | T10: L34, L55 | U10: type=chronology name=East Capitol Street line network=Washington, D.C. streetcars operator=Metropolitan Railroad start_date=1872 end_date=1962 ref:streetcar_project=L09 ref=40;96 description=Later operators: WRECo; Capital Transit; D.C. Transit source=WP; MPD; CRF Dated route relations in this chronology: 1872–1896: 6 ways; operator=Metropolitan Railroad; railway:traction=horse 1896–1902: 11 ways; operator=Metropolitan Railroad; railway:traction=electric 1902–1934: 11 ways; operator=Washington Railway & Electric; railway:traction=electric 1934–1956: 11 ways; operator=Capital Transit; railway:traction=electric 1956–1962: 11 ways; operator=D.C. Transit; railway:traction=electric
A11: L10 | B11: Connecticut Avenue line (south) | C11: Connecticut Ave from 17th St & New York Ave / White House north to Boundary St (Florida Ave) | D11: DC | E11: Connecticut Avenue & Park Railway (chartered 1868) | F11: Metropolitan (1874); WRECo; Capital Transit; D.C. Transit | G11: Horse (April 1873) → electric (1896) | H11: 1873 | I11: 1873 | J11: — | K11: 1896 | L11: 42, 44 | M11: Dec 3, 1961 | N11: 1961 | O11: Bus 42 | P11: Horsecars ran only to P St in 1873; the track north to Florida Ave was paved over and then revived as a shuttle in 1883. Dupont Circle underpass opened Nov 2, 1949. Conflict: the 1880 statistical map shows track on Connecticut Ave to S St, although Tindall and Wikipedia say the section north of P St was paved over until 1883. 1912 map: the line ran on 17th St between H St and K St, joining Connecticut Ave at Farragut Square. | Q11: WP; MPD; CRF; MAP1880 | R11: 1.91 | S11: 0 | T11: — | U11: type=chronology name=Connecticut Avenue line (south) network=Washington, D.C. streetcars operator=Connecticut Avenue & Park Railway (chartered 1868) start_date=1873 end_date=1961 ref:streetcar_project=L10 ref=42;44 description=Later operators: Metropolitan (1874); WRECo; Capital Transit; D.C. Transit source=WP; MPD; CRF; MAP1880 Dated route relations in this chronology: 1873–1883: 2 ways; operator=Connecticut Avenue & Park Railway; railway:traction=horse 1883–1896: 4 ways; operator=Connecticut Avenue & Park Railway; railway:traction=horse 1896–1902: 4 ways; operator=Connecticut Avenue & Park Railway; railway:traction=electric 1902–1934: 4 ways; operator=Washington Railway & Electric; railway:traction=electric 1934–1956: 4 ways; operator=Capital Transit; railway:traction=electric 1956–1961: 4 ways; operator=D.C. Transit; railway:traction=electric
A12: L11 | B12: Mount Pleasant extension | C12: Columbia Rd from Connecticut & Florida Aves to 18th St (1897), then Columbia Rd east to 'old Sixteenth St' (today's Mount Pleasant St) and north to Park St (1900) | D12: DC | E12: Metropolitan Railroad | F12: WRECo; Capital Transit; D.C. Transit | G12: Electric | H12: 1900 | I12: — | J12: — | K12: 1900 | L12: 42 (Mt. Pleasant) | M12: Dec 3, 1961 | N12: 1961 | O12: Bus 42/43 | P12: Authorized Feb 27, 1897; service began June 6, 1900 (the earlier 1896 date was wrong). | Q12: WP-Metro; TIN; LAWS; CRF | R12: 2.39 | S12: 0 | T12: — | U12: type=chronology name=Mount Pleasant extension network=Washington, D.C. streetcars operator=Metropolitan Railroad start_date=1900 end_date=1961 ref:streetcar_project=L11 ref=42 description=Later operators: WRECo; Capital Transit; D.C. Transit source=WP-Metro; TIN; LAWS; CRF Dated route relations in this chronology: 1900–1902: 2 ways; operator=Metropolitan Railroad; railway:traction=electric 1902–1934: 2 ways; operator=Washington Railway & Electric; railway:traction=electric 1934–1956: 2 ways; operator=Capital Transit; railway:traction=electric 1956–1961: 2 ways; operator=D.C. Transit; railway:traction=electric
A13: L12 | B13: Georgia Avenue (7th St Extended / Brightwood) line | C13: Georgia Ave (Brightwood Ave) from Florida Ave to Rock Creek Church Rd (horse, 1873), then to Brightwood and the Silver Spring district line | D13: DC | E13: Boundary & Silver Spring Railway (chartered 1872; bought by Metropolitan Dec 1872) | F13: Brightwood Railway (1888/1890); WRECo; Capital Transit; D.C. Transit | G13: Horse → Judson pneumatic trial (1889–90, failed) → overhead electric ordered 1892 → underground conduit ordered 1898 | H13: 1873 | I13: 1873 | J13: — | K13: 1890 | L13: 70 (Georgia Ave to Brightwood) | M13: Jan 3, 1960 | N13: 1960 | O13: Bus 70 | P13: CRF gives electric 1890; Wikipedia says Congress ordered overhead electric in 1892. The 1880 map (and Berman's 2019 redraw) labels the city end of this line 'Pleasant Plains', possibly because the map stops at the city limit. | Q13: WP; MPD; CRF | R13: 7.61 | S13: 0.06 | T13: L41 | U13: type=chronology name=Georgia Avenue (7th St Extended / Brightwood) line network=Washington, D.C. streetcars operator=Boundary & Silver Spring Railway (chartered 1872; bought by Metropolitan Dec 1872) start_date=1873 end_date=1960 ref:streetcar_project=L12 ref=70 description=Later operators: Brightwood Railway (1888/1890); WRECo; Capital Transit; D.C. Transit source=WP; MPD; CRF Dated route relations in this chronology: 1873–1890: 4 ways; operator=Boundary & Silver Spring Railway; railway:traction=horse 1890–1893: 7 ways; operator=Boundary & Silver Spring Railway; railway:traction=electric 1893–1902: 10 ways; operator=Boundary & Silver Spring Railway; railway:traction=electric 1902–1934: 10 ways; operator=Washington Railway & Electric; railway:traction=electric 1934–1956: 10 ways; operator=Capital Transit; railway:traction=electric 1956–1960: 10 ways; operator=D.C. Transit; railway:traction=electric
A14: L13 | B14: Takoma branch (Brightwood Railway) | C14: Georgia Ave to Butternut St (then Umatilla St) and 4th St NW, Takoma Park | D14: DC | E14: Brightwood Railway | F14: WRECo; Capital Transit; D.C. Transit | G14: Electric | H14: 1893 | I14: — | J14: — | K14: 1892 | L14: 72 (Georgia Ave–Takoma) | M14: Jan 3, 1960 | N14: 1960 | O14: Bus 52/54 | Q14: WP; CRF | R14: 0.77 | S14: 0 | T14: — | U14: type=chronology name=Takoma branch (Brightwood Railway) network=Washington, D.C. streetcars operator=Brightwood Railway start_date=1893 end_date=1960 ref:streetcar_project=L13 ref=72 description=Later operators: WRECo; Capital Transit; D.C. Transit source=WP; CRF Dated route relations in this chronology: 1893–1902: 1 ways; operator=Brightwood Railway; railway:traction=electric 1902–1934: 1 ways; operator=Washington Railway & Electric; railway:traction=electric 1934–1956: 1 ways; operator=Capital Transit; railway:traction=electric 1956–1960: 1 ways; operator=D.C. Transit; railway:traction=electric
A15: L14 | B15: Soldiers' Home / Upshur Street line | C15: Soldiers' Home by a route off Georgia Ave; CRF also lists an Upshur St line on old route 74 | D15: DC | E15: WRECo predecessor (not identified) | F15: WRECo; Capital Transit; D.C. Transit | G15: Electric | H15: 1893 | I15: — | J15: — | K15: 1893 | L15: 74 | M15: Jan 3, 1960 | N15: 1960 | O15: Bus 60 | P15: The original builder isn't named in the sources checked. | Q15: CRF; GDC | R15: 1.06 | S15: 0 | T15: — | U15: type=chronology name=Soldiers' Home / Upshur Street line network=Washington, D.C. streetcars operator=WRECo predecessor (not identified) start_date=1893 end_date=1960 ref:streetcar_project=L14 ref=74 description=Later operators: WRECo; Capital Transit; D.C. Transit source=CRF; GDC Dated route relations in this chronology: 1893–1902: 1 ways; operator=WRECo predecessor; railway:traction=electric 1902–1934: 1 ways; operator=Washington Railway & Electric; railway:traction=electric 1934–1956: 1 ways; operator=Capital Transit; railway:traction=electric 1956–1960: 1 ways; operator=D.C. Transit; railway:traction=electric
A16: L15 | B16: Columbia Railway – H Street line | C16: Charter route: 15th St & New York Ave NW via New York Ave, K St, Massachusetts Ave and H St NW/NE to 15th St NE | D16: DC | E16: Columbia Railway | F16: Washington Traction & Electric (1899); WRECo (1902); Capital Transit | G16: Horse → cable (Mar 9, 1895; the last cable line built in the US) → electric (July 22, 1899) | H16: 1870 | I16: 1870/1871 | J16: 1895 | K16: 1899 | L16: 10 (Rosslyn–Benning via H St) | M16: May 1, 1949 | N16: 1949 | O16: Bus X2 | P16: The last cable car in DC ran July 23, 1899. Revived as the DC Streetcar (2016–2026). Tundria: H St–Benning Rd track closed May 1, 1949. | Q16: WP; MPD; CRF | R16: 4.56 | S16: 0.22 | T16: L03, L06 | U16: type=chronology name=Columbia Railway – H Street line network=Washington, D.C. streetcars operator=Columbia Railway start_date=1870 end_date=1949 ref:streetcar_project=L15 ref=10 description=Later operators: Washington Traction & Electric (1899); WRECo (1902); Capital Transit source=WP; MPD; CRF Dated route relations in this chronology: 1870–1895: 13 ways; operator=Columbia Railway; railway:traction=horse 1895–1899: 13 ways; operator=Columbia Railway; railway:traction=cable 1899–1902: 13 ways; operator=Columbia Railway; railway:traction=electric 1902–1934: 13 ways; operator=Washington Railway & Electric; railway:traction=electric 1934–1949: 13 ways; operator=Capital Transit; railway:traction=electric
A17: L16 | B17: Benning Road – Kenilworth branch | C17: Benning Rd NE east from 15th & H NE across the Anacostia to Kenilworth | D17: DC | E17: Columbia Railway | F17: WRECo; Capital Transit | G17: Electric | H17: 1898 | I17: — | J17: — | K17: 1898 | L17: 10 | M17: May 1, 1949 | N17: 1949 | O17: Bus V8 / X2 | P17: Benning Rd car barn built 1941. 1912 map (audit): the branch left Benning Rd just west of Minnesota Ave and ran northeast on its own alignment to Kenilworth; redrawn. | Q17: WP; CRF; MPD | R17: 6.23 | S17: 4.98 | T17: L17, V08 | U17: type=chronology name=Benning Road – Kenilworth branch network=Washington, D.C. streetcars operator=Columbia Railway start_date=1898 end_date=1949 ref:streetcar_project=L16 ref=10 description=Later operators: WRECo; Capital Transit source=WP; CRF; MPD Dated route relations in this chronology: 1898–1902: 6 ways; operator=Columbia Railway; railway:traction=electric 1902–1934: 6 ways; operator=Washington Railway & Electric; railway:traction=electric 1934–1949: 6 ways; operator=Capital Transit; railway:traction=electric
A18: L17 | B18: Seat Pleasant branch | C18: Benning Rd to Deanwood Junction and Seat Pleasant, MD (connection with the Chesapeake Beach Railway) | D18: DC/MD | E18: Columbia Railway | F18: WRECo; Capital Transit | G18: Electric | H18: 1900 | I18: — | J18: — | K18: 1898/1900 | L18: 12 (Seat Pleasant) | M18: May 1, 1949 (Wikipedia: Kenilworth–Seat Pleasant bus substitution 1948) | N18: 1949 | O18: Bus U8 | P18: Seat Pleasant loop built 1945. 1912 map: ran from Benning Rd up Minnesota Ave and east along Deane Ave (today's Nannie Helen Burroughs Ave) and Dix St to the District line, matching Berman's 1942 map. 1912 map (audit): shared the Kenilworth branch alignment from Benning Rd, then ran straight along Deane Ave (Nannie Helen Burroughs Ave) to the District line; redrawn. | Q18: WP; MPD; CRF | R18: 4.64 | S18: 1.56 | T18: L16, V08 | U18: type=chronology name=Seat Pleasant branch network=Washington, D.C. streetcars operator=Columbia Railway start_date=1900 end_date=1949 ref:streetcar_project=L17 ref=12 description=Later operators: WRECo; Capital Transit source=WP; MPD; CRF Dated route relations in this chronology: 1900–1902: 4 ways; operator=Columbia Railway; railway:traction=electric 1902–1934: 4 ways; operator=Washington Railway & Electric; railway:traction=electric 1934–1949: 4 ways; operator=Capital Transit; railway:traction=electric
A19: L18 | B19: Anacostia & Potomac River Railroad main line | C19: Along M St from the Maine Ave/M St waterfront to 11th St SE, across the Navy Yard Bridge to Uniontown (Nichols Ave & V St SE), as mapped in 1880. 1888: extensions toward Congressional Cemetery and Center Market; Nichols Ave toward St. Elizabeths (Government Hospital for the Insane) | D19: DC | E19: Anacostia & Potomac River Railroad | F19: WRECo (controlling stock 1912); Capital Transit | G19: Horse → electric (April 1900, the last horse line in DC) | H19: 1875 | I19: 1875 | J19: — | K19: 1900 | L19: — (Anacostia service later part of routes 54/A2 corridor) | M19: Between 1924 and 1942 (still drawn on the 1924 Rand McNally map; nothing crosses the Anacostia on the 1942 map) | O19: — | P19: First line to cross the Anacostia River. Probably ended with the 1935 Anacostia conversions, but no source confirms it. Map: the 1888 Center Market branch (G St, 4th St, E St and Canal St SE) is drawn on the 1912 map. 1912 map: the line ran up 11th St SE to G St; there is no track on M St SE, on 7th St SE, or on G St east of 11th St, so those sections are drawn only to 1900 (estimated). 1912 map: the Center Market branch ran up Canal St, west on Maryland Ave, north on 4½ St and along Missouri Ave and B St to 7th St. 1912 map: M St SW between the waterfront and 4½ St was still in use. | Q19: WP; MPD; MAP1880; MAP1910; MAP1924; MAP1942 | R19: 12.53 | S19: 2.89 | T19: L01, L02, L08, L22 | U19: type=chronology name=Anacostia & Potomac River Railroad main line network=Washington, D.C. streetcars operator=Anacostia & Potomac River Railroad start_date=1875 end_date=1935 ref:streetcar_project=L18 end_date:edtf=1935~ ref=54 description=Later operators: WRECo (controlling stock 1912); Capital Transit source=WP; MPD; MAP1880; MAP1910; MAP1924; MAP1942 Dated route relations in this chronology: 1875–1888: 7 ways; operator=Anacostia & Potomac River Railroad; railway:traction=horse 1888–1900: 21 ways; operator=Anacostia & Potomac River Railroad; railway:traction=horse 1900–1912: 16 ways; operator=Anacostia & Potomac River Railroad; railway:traction=electric 1912–1934: 16 ways; operator=Washington Railway & Electric; railway:traction=electric 1934–1935: 16 ways; operator=Capital Transit; railway:traction=electric
A20: L19 | B20: 11th Street line | C20: 11th St: north to Boundary St and south to Water St SW (Belt, 1881); A&PR extended it from F St NW to Florida Ave (1898) and by double track north on 11th St to Lydecker Ave (1902); later to 11th & Monroe NW and through-routed to Anacostia | D20: DC | E20: Belt Railway (11th St line, 1881); extended by the A&PR (1898) | F20: Washington Traction & Electric; WRECo; Capital Transit; D.C. Transit | G20: Horse → electric (1900) | H20: 1875 | I20: 1875 | J20: — | K20: 1900 | L20: 60 (11th & Monroe); 62; 64 | M20: Dec 3, 1961 | N20: 1961 | O20: Bus 66 | Q20: MPD; CRF; GDC; LAWS | R20: 4.03 | S20: 1.49 | T20: L22 | U20: type=chronology name=11th Street line network=Washington, D.C. streetcars operator=Belt Railway (11th St line, 1881); extended by the A&PR (1898) start_date=1875 end_date=1961 ref:streetcar_project=L19 ref=60;62;64 description=Later operators: Washington Traction & Electric; WRECo; Capital Transit; D.C. Transit source=MPD; CRF; GDC; LAWS Dated route relations in this chronology: 1875–1900: 8 ways; operator=Belt Railway; railway:traction=horse 1900–1902: 8 ways; operator=Belt Railway; railway:traction=electric 1902–1912: 10 ways; operator=Belt Railway; railway:traction=electric 1912–1934: 10 ways; operator=Washington Railway & Electric; railway:traction=electric 1934–1956: 10 ways; operator=Capital Transit; railway:traction=electric 1956–1961: 10 ways; operator=D.C. Transit; railway:traction=electric
A21: L20 | B21: Capital Railway – Anacostia–Congress Heights | C21: Navy Yard Bridge – Nichols Ave SE to Congress Heights (Upsal St by 1898); later extended past Alabama Ave to Sterling St SE | D21: DC | E21: Capital Railway (chartered Mar 2, 1895) | F21: A&PR (1899); WRECo; Capital Transit | G21: Brown magnetic surface contact (1897, failed) and double-overhead on the bridge → electric | H21: 1896 | I21: — | J21: — | K21: 1896 | L21: — (bus A2) | M21: June 16, 1935 (CRF) / last car July 16, 1935 (Wikipedia) | N21: 1935 | O21: Bus A2 | P21: Anacostia's first electric line. | Q21: WP; MPD; CRF | R21: 1.73 | S21: 0.68 | T21: L21 | U21: type=chronology name=Capital Railway – Anacostia–Congress Heights network=Washington, D.C. streetcars operator=Capital Railway (chartered Mar 2, 1895) start_date=1896 end_date=1935 ref:streetcar_project=L20 description=Later operators: A&PR (1899); WRECo; Capital Transit source=WP; MPD; CRF Dated route relations in this chronology: 1896–1912: 10 ways; operator=Capital Railway; railway:traction=electric 1912–1934: 10 ways; operator=Washington Railway & Electric; railway:traction=electric 1934–1935: 10 ways; operator=Capital Transit; railway:traction=electric
A22: L21 | B22: Portland Street / Firth Sterling spur | C22: Nichols Ave along Portland St to the Firth Sterling Steel works (now part of Joint Base Anacostia-Bolling) | D22: DC | E22: WRECo | F22: — | G22: Electric (single track, doubled 1916) | H22: 1912 | I22: — | J22: — | K22: 1912 | L22: — | M22: Service suspended by 1923 | N22: 1923 | O22: — | P22: About one mile of track. | Q22: MPD | R22: 1.41 | S22: 0.68 | T22: L20 | U22: type=chronology name=Portland Street / Firth Sterling spur network=Washington, D.C. streetcars operator=WRECo start_date=1912 end_date=1923 ref:streetcar_project=L21 source=MPD Dated route relations in this chronology: 1912–1923: 10 ways; operator=Washington Railway & Electric; railway:traction=electric
A23: L22 | B23: Belt Railway loop | C23: Capitol – 1st St SW – Maryland & Virginia Aves SW – 12th St – Ohio Ave – 14th St – O St NW (10 blocks east) – 4th St – G St – 1st St NW; P St NW westbound track (1876) | D23: DC | E23: Capitol, North O Street & South Washington Railway (renamed Belt Railway 1893) | F23: Anacostia & Potomac River (1898); WRECo | G23: Horse → compressed-air trial (1896) → electric conduit (1899) | H23: 1875 | I23: 1875 | J23: — | K23: 1899 | L23: — | M23: Absorbed into other routes; end date not stated | O23: — | P23: 8.5 miles of track. Car barn at 3rd & B (Independence) Sts SW. 1912 map: the loop's south side ran along Maryland Ave SW from 12th St to the Capitol grounds. 1912 map: a branch ran down 11th St SW to the waterfront and along Water St to 7th St. 1912 map (audit): south of New York Ave the loop used New York Ave and 5th St to reach G St, not 4th St. | Q23: WP; MPD | R23: 11.36 | S23: 4.99 | T23: L01, L02, L04, L18, L19, L33, L48, L51, L55, L58, V01 | U23: type=chronology name=Belt Railway loop network=Washington, D.C. streetcars operator=Capitol, North O Street & South Washington Railway (renamed Belt Railway 1893) start_date=1875 end_date=1933 ref:streetcar_project=L22 end_date:edtf=1933~ description=Later operators: Anacostia & Potomac River (1898); WRECo source=WP; MPD Dated route relations in this chronology: 1875–1876: 40 ways; operator=Capitol, North O Street & South Washington Railway; railway:traction=horse 1876–1899: 44 ways; operator=Capitol, North O Street & South Washington Railway; railway:traction=horse 1899–1912: 44 ways; operator=Capitol, North O Street & South Washington Railway; railway:traction=electric 1912–1933: 44 ways; operator=Washington Railway & Electric; railway:traction=electric
A24: L23 | B24: Eckington & Soldiers' Home Railway | C24: Charter: New York Ave from 7th St to 3rd St NE, 3rd St to T St, T St to 4th St, 4th St to Bunker Hill Rd (Michigan Ave). As built: 7th & New York Ave via Boundary St, Eckington Pl, R St, 3rd St and T St NE to the car barn at 4th & T NE | D24: DC | E24: Eckington & Soldiers' Home Railway | F24: City & Suburban (1898); WRECo; Capital Transit | G24: DC's first electric line (overhead, Oct 17, 1888) → batteries (1891–93) → horses → compressed air (1896) → conduit (1899) | H24: 1888 | I24: — | J24: — | K24: 1888 | L24: — | M24: Not stated for the trunk | O24: — | P24: 2.5 miles. Also tried the Wheless and Willis magnetic surface-contact systems on North Capitol St. 1912 map: the Eckington loop used both 2nd and 3rd Sts NE between R and T Sts. | Q24: WP; MPD | R24: 3.11 | S24: 0.14 | T24: L25 | U24: type=chronology name=Eckington & Soldiers' Home Railway network=Washington, D.C. streetcars operator=Eckington & Soldiers' Home Railway start_date=1888 end_date=1958 ref:streetcar_project=L23 end_date:edtf=1958~ description=Later operators: City & Suburban (1898); WRECo; Capital Transit source=WP; MPD Dated route relations in this chronology: 1888–1902: 10 ways; operator=Eckington & Soldiers' Home Railway; railway:traction=electric 1902–1934: 10 ways; operator=Washington Railway & Electric; railway:traction=electric 1934–1956: 10 ways; operator=Capital Transit; railway:traction=electric 1956–1958: 10 ways; operator=D.C. Transit; railway:traction=electric
A25: L24 | B25: NE 4th Street branch | C25: 4th St NE north to Michigan Ave; later a Michigan Ave extension to the B&O Metropolitan Branch | D25: DC | E25: Eckington & Soldiers' Home Railway | F25: WRECo | G25: Electric | H25: 1888 | I25: — | J25: — | K25: 1888 | L25: — (bus F4/G8) | M25: 1920s | N25: 1925 | O25: Bus G8 | P25: CRF gives '1920s' only; end year approximate. | Q25: WP; CRF | R25: 1.74 | S25: 0 | T25: — | U25: type=chronology name=NE 4th Street branch network=Washington, D.C. streetcars operator=Eckington & Soldiers' Home Railway start_date=1888 end_date=1925 ref:streetcar_project=L24 description=Later operators: WRECo source=WP; CRF Dated route relations in this chronology: 1888–1902: 2 ways; operator=Eckington & Soldiers' Home Railway; railway:traction=electric 1902–1925: 2 ways; operator=Washington Railway & Electric; railway:traction=electric
A26: L25 | B26: Glenwood Cemetery extension | C26: T St, 2nd St and V St NE to Glenwood Cemetery | D26: DC | E26: Eckington & Soldiers' Home Railway | F26: — | G26: Electric | H26: 1889 | I26: — | J26: — | K26: 1889 | L26: — | M26: 1894 (unprofitable) | N26: 1894 | O26: — | Q26: WP; MPD | R26: 1.62 | S26: 1.05 | T26: L23, L26 | U26: type=chronology name=Glenwood Cemetery extension network=Washington, D.C. streetcars operator=Eckington & Soldiers' Home Railway start_date=1889 end_date=1894 ref:streetcar_project=L25 source=WP; MPD Dated route relations in this chronology: 1889–1894: 6 ways; operator=Eckington & Soldiers' Home Railway; railway:traction=electric
A27: L26 | B27: North Capitol Street / Brookland line | C27: North Capitol St to the Soldiers' Home; extended to Brookland (Catholic University) 1899–1900; Brookland/Quincy St loop 1948 | D27: DC | E27: Eckington & Soldiers' Home Railway | F27: WRECo; Capital Transit; D.C. Transit | G27: Electric (1890 per CRF) | H27: 1890 | I27: — | J27: — | K27: 1890 | L27: 80 | M27: Sept 7, 1958 (CRF) / 1959 (Wikipedia) | N27: 1958 | O27: Bus 80 | P27: 1912 map: continued north on 12th St NE past Monroe St to about Randolph St. | Q27: WP; MPD; CRF; GDC | R27: 5.97 | S27: 1.12 | T27: L25, L33 | U27: type=chronology name=North Capitol Street / Brookland line network=Washington, D.C. streetcars operator=Eckington & Soldiers' Home Railway start_date=1890 end_date=1958 ref:streetcar_project=L26 ref=80 description=Later operators: WRECo; Capital Transit; D.C. Transit source=WP; MPD; CRF; GDC Dated route relations in this chronology: 1890–1899: 10 ways; operator=Eckington & Soldiers' Home Railway; railway:traction=electric 1899–1902: 12 ways; operator=Eckington & Soldiers' Home Railway; railway:traction=electric 1902–1934: 12 ways; operator=Washington Railway & Electric; railway:traction=electric 1934–1956: 12 ways; operator=Capital Transit; railway:traction=electric 1956–1958: 12 ways; operator=D.C. Transit; railway:traction=electric
A28: L27 | B28: G Street extension | C28: 5th St from New York Ave to G St, then G St NW to 15th St (c.1890); 1892–94 downtown loops via 1st St, C St and D St NW, New Jersey Ave, and 5th St, Louisiana Ave, 6th St and B St NW to near 7th St (Center Market) | D28: DC | E28: Eckington & Soldiers' Home Railway | F28: WRECo | G28: Battery trials (1891–93), then electric | H28: 1891 | I28: — | J28: — | K28: 1891 | L28: — | M28: Not stated | O28: — | P28: Authorized 1890. | Q28: MPD; LAWS | R28: 1.91 | S28: 0 | T28: — | U28: type=chronology name=G Street extension network=Washington, D.C. streetcars operator=Eckington & Soldiers' Home Railway start_date=1891 end_date=1958 ref:streetcar_project=L27 end_date:edtf=1958~ description=Later operators: WRECo source=MPD; LAWS Dated route relations in this chronology: 1891–1902: 11 ways; operator=Eckington & Soldiers' Home Railway; railway:traction=electric 1902–1934: 11 ways; operator=Washington Railway & Electric; railway:traction=electric 1934–1956: 11 ways; operator=Capital Transit; railway:traction=electric 1956–1958: 11 ways; operator=D.C. Transit; railway:traction=electric
A29: L28 | B29: Rhode Island Avenue – College Park line | C29: Rhode Island Ave NE from 4th St NE (connection with Eckington line) to Mount Rainier (1897), Brentwood (1898), Hyattsville and Riverdale (1899), then College Park and Berwyn | D29: DC/MD | E29: Maryland & Washington Railway / City & Suburban Railway | F29: WRECo (fully 1926); Capital Transit; D.C. Transit | G29: Electric | H29: 1897 | I29: — | J29: — | K29: 1897 | L29: 82 (College Park); P6 bus later | M29: Sept 7, 1958 (Route 82, one of the first abandoned by D.C. Transit) | N29: 1958 | O29: Bus 82 / P6 | P29: Truncated at Beltsville by 1948 and at Berwyn by 1956. Right-of-way partly used by the Rhode Island Ave Trolley Trail. | Q29: WPMD; MPD; CRF | R29: 11.96 | S29: 0.24 | T29: L29 | U29: type=chronology name=Rhode Island Avenue – College Park line network=Washington, D.C. streetcars operator=Maryland & Washington Railway / City & Suburban Railway start_date=1897 end_date=1958 ref:streetcar_project=L28 ref=82 description=Later operators: WRECo (fully 1926); Capital Transit; D.C. Transit source=WPMD; MPD; CRF Dated route relations in this chronology: 1897–1899: 1 ways; operator=Maryland & Washington Railway / City & Suburban Railway; railway:traction=electric 1899–1900: 2 ways; operator=Maryland & Washington Railway / City & Suburban Railway; railway:traction=electric 1900–1902: 4 ways; operator=Maryland & Washington Railway / City & Suburban Railway; railway:traction=electric 1902–1934: 4 ways; operator=Washington Railway & Electric; railway:traction=electric 1934–1956: 4 ways; operator=Capital Transit; railway:traction=electric 1956–1958: 4 ways; operator=D.C. Transit; railway:traction=electric
A30: L29 | B30: Berwyn – Beltsville – Laurel extension | C30: Riverdale–College Park–Berwyn–Branchville–Beltsville–Contee–Laurel, MD | D30: MD | E30: Columbia & Maryland Ry / Berwyn & Laurel Electric RR / Washington, Berwyn & Laurel Electric RR | F30: City & Suburban; WRECo (1910); Capital Transit | G30: Electric | H30: 1902 | I30: — | J30: — | K30: 1902 | L30: 84 (Branchville–Beltsville) | M30: Branchville–Beltsville: July 31, 1949 (CRF); Laurel end not stated | N30: 1949 | O30: Discontinued | P30: Direct Treasury–Laurel service began 1902. | Q30: WPMD; MPD; CRF | R30: 13.68 | S30: 0.24 | T30: L28 | U30: type=chronology name=Berwyn – Beltsville – Laurel extension network=Washington, D.C. streetcars operator=Columbia & Maryland Ry / Berwyn & Laurel Electric RR / Washington, Berwyn & Laurel Electric RR start_date=1902 end_date=1949 ref:streetcar_project=L29 ref=84 description=Later operators: City & Suburban; WRECo (1910); Capital Transit source=WPMD; MPD; CRF Dated route relations in this chronology: 1902–1934: 4 ways; operator=Washington Railway & Electric; railway:traction=electric 1934–1948: 4 ways; operator=Capital Transit; railway:traction=electric 1948–1949: 3 ways; operator=Capital Transit; railway:traction=electric
A31: L30 | B31: Rock Creek Railway – Connecticut Avenue line | C31: Florida Ave (2 blocks east of Connecticut) – 18th St – Calvert St bridge (1891) – Connecticut Ave to Chevy Chase Circle and Chevy Chase Lake, MD | D31: DC/MD | E31: Rock Creek Railway | F31: Capital Traction (1895); Capital Transit | G31: Overhead outside the city; Love conduit inside (1893–99) | H31: 1890 | I31: — | J31: — | K31: 1892 | L31: — (buses L2/L6) | M31: Sept 16, 1935 (Calvert St bridge to Chevy Chase Lake) | N31: 1935 | O31: Bus L2 / L6 | P31: Florida Ave stub (Connecticut Ave–18th St) opened 1890 and was removed 1899. Calvert St bridge completed July 21, 1891. Suburban line opened Sept 16 (Wikipedia) or 18 (NRHP), 1892. Through service to Kensington from 1923. Last cars Sept 15, 1935. | Q31: WP; MPD; CRF | R31: 10.18 | S31: 0 | T31: — | U31: type=chronology name=Rock Creek Railway – Connecticut Avenue line network=Washington, D.C. streetcars operator=Rock Creek Railway start_date=1890 end_date=1935 ref:streetcar_project=L30 description=Later operators: Capital Traction (1895); Capital Transit source=WP; MPD; CRF Dated route relations in this chronology: 1890–1892: 1 ways; operator=Rock Creek Railway; railway:traction=horse 1892–1895: 4 ways; operator=Rock Creek Railway; railway:traction=electric 1895–1899: 4 ways; operator=Capital Traction; railway:traction=electric 1899–1934: 3 ways; operator=Capital Traction; railway:traction=electric 1934–1935: 3 ways; operator=Capital Transit; railway:traction=electric
A32: L31 | B32: U Street line | C32: U St east from 18th St to 7th St NW (1893, Love conduit), later the U St crosstown | D32: DC | E32: Rock Creek Railway | F32: Capital Traction; Capital Transit; D.C. Transit | G32: Electric (Love conduit 1893, standard conduit 1899) | H32: 1893 | I32: — | J32: — | K32: 1892/1893 | L32: 90, 92 (U St crosstown) | M32: Jan 28, 1962 | N32: 1962 | O32: Bus 90/92 | P32: Opened Mar 2, 1893 (18th & Florida to 7th St). Love conduit replaced by sliding shoe in 1899. In 1946, routes 90/92 started at the National Zoological Park via Calvert St (Tundria lists 16th St where other sources say 18th St). | Q32: WP; MPD; CRF; GGW; TUN | R32: 1.86 | S32: 0.09 | T32: L06 | U32: type=chronology name=U Street line network=Washington, D.C. streetcars operator=Rock Creek Railway start_date=1893 end_date=1962 ref:streetcar_project=L31 ref=90;92 description=Later operators: Capital Traction; Capital Transit; D.C. Transit source=WP; MPD; CRF; GGW; TUN Dated route relations in this chronology: 1893–1895: 6 ways; operator=Rock Creek Railway; railway:traction=electric 1895–1934: 6 ways; operator=Capital Traction; railway:traction=electric 1934–1956: 6 ways; operator=Capital Transit; railway:traction=electric 1956–1962: 6 ways; operator=D.C. Transit; railway:traction=electric
A33: L32 | B33: Florida Avenue / 8th Street extension | C33: U St line extended east on Florida Ave NW/NE to 8th St NE, then south on 8th St NE/SE to the Navy Yard | D33: DC | E33: Capital Traction (Act of May 23, 1908; per Tindall and Wikipedia's Capital Traction article; Wikipedia's main article says WRECo) | F33: Capital Transit; D.C. Transit | G33: Electric | H33: 1908 | I33: — | J33: — | K33: 1908 | L33: 90, 92 | M33: Jan 28, 1962 | N33: 1962 | O33: Bus 90/92 | P33: Rails still buried under 8th St SE. Drawn on the 1910 and 1924 Rand McNally maps. 1912 map: Capital Traction track on F St NE linked Union Station with the 8th St line. | Q33: WP; CRF | R33: 6.51 | S33: 0.89 | T33: L01, L48 | U33: type=chronology name=Florida Avenue / 8th Street extension network=Washington, D.C. streetcars operator=Capital Traction (Act of May 23, 1908; per Tindall and Wikipedia's Capital Traction article; Wikipedia's main article says WRECo) start_date=1908 end_date=1962 ref:streetcar_project=L32 ref=90;92 description=Later operators: Capital Transit; D.C. Transit source=WP; CRF Dated route relations in this chronology: 1908–1934: 15 ways; operator=Capital Traction; railway:traction=electric 1934–1956: 15 ways; operator=Capital Transit; railway:traction=electric 1956–1962: 15 ways; operator=D.C. Transit; railway:traction=electric
A34: L33 | B34: New Jersey Avenue line | C34: Florida Ave & New Jersey Ave via New Jersey Ave and Massachusetts Ave to the Union Station plaza (Act of May 23, 1908) | D34: DC | E34: Capital Traction | F34: Capital Transit; D.C. Transit | G34: Electric | H34: 1908 | I34: — | J34: — | K34: 1908 | L34: 90 (old route) | M34: Jan 28, 1962 | N34: 1962 | O34: — | Q34: CRF | R34: 2.31 | S34: 0.35 | T34: L22, L26, L48, L55 | U34: type=chronology name=New Jersey Avenue line network=Washington, D.C. streetcars operator=Capital Traction start_date=1908 end_date=1962 ref:streetcar_project=L33 ref=90 description=Later operators: Capital Transit; D.C. Transit source=CRF Dated route relations in this chronology: 1908–1934: 9 ways; operator=Capital Traction; railway:traction=electric 1934–1956: 9 ways; operator=Capital Transit; railway:traction=electric 1956–1962: 9 ways; operator=D.C. Transit; railway:traction=electric
A35: L34 | B35: Union Station trackage | C35: Delaware Ave NE and Massachusetts Ave NE to Union Station; C St tunnel under Capitol Plaza (1934) | D35: DC | E35: Capital Traction & WRECo | F35: Capital Transit; D.C. Transit | G35: Electric | H35: 1908 | I35: — | J35: — | K35: 1908 | L35: 90, 92 | M35: Jan 1962 | N35: 1962 | O35: — | P35: Service began June 24, 1908 (Wikipedia Capital Traction article) or Dec 6, 1908 (NRHP). Capitol Plaza tunnel opened 1934. Map: joint track ran south from Union Station on 1st St NE/SE to Pennsylvania Ave SE (1912 map; route 90 in 1946). | Q35: WP; MPD | R35: 1.71 | S35: 0.67 | T35: L01, L02, L09, L55 | U35: type=chronology name=Union Station trackage network=Washington, D.C. streetcars operator=Capital Traction & WRECo start_date=1908 end_date=1962 ref:streetcar_project=L34 ref=90;92 description=Later operators: Capital Transit; D.C. Transit source=WP; MPD Dated route relations in this chronology: 1908–1934: 8 ways; operator=Capital Traction; railway:traction=electric 1934–1956: 8 ways; operator=Capital Transit; railway:traction=electric 1956–1962: 8 ways; operator=D.C. Transit; railway:traction=electric
A36: L35 | B36: Kensington Railway | C36: Chevy Chase Lake north along Connecticut Ave to University Blvd, Kensington; extended 1.5 miles north by 1916 | D36: MD | E36: Chevy Chase Lake & Kensington Railway (1894) | F36: Kensington Railway; leased to Capital Traction 1923–33 | G36: Electric (single track) | H36: 1895 | I36: — | J36: — | K36: 1895 | L36: — | M36: Sept 15, 1935 | N36: 1935 | O36: — | P36: Opened May 30, 1895. Right-of-way became Kensington Parkway. | Q36: WPMD | R36: 3.76 | S36: 0 | T36: — | U36: type=chronology name=Kensington Railway network=Washington, D.C. streetcars operator=Chevy Chase Lake & Kensington Railway (1894) start_date=1895 end_date=1935 ref:streetcar_project=L35 description=Later operators: Kensington Railway; leased to Capital Traction 1923–33 source=WPMD Dated route relations in this chronology: 1895–1935: 1 ways; operator=Chevy Chase Lake & Kensington Railway; railway:traction=electric
A37: L36 | B37: Georgetown & Tennallytown line | C37: M St NW up 32nd St and Wisconsin Ave (Georgetown & Rockville Rd) to Tenleytown and Friendship Heights | D37: DC | E37: Georgetown & Tennallytown Railway | F37: Washington Traction & Electric; WRECo (fully 1926); Capital Transit; D.C. Transit | G37: Overhead electric (1890) | H37: 1890 | I37: — | J37: — | K37: 1890 | L37: 30, 31 (Wisconsin Ave) | M37: Jan 3, 1960 | N37: 1960 | O37: Bus 30s | P37: Opened Apr 25, 1890. | Q37: WP; MPD; CRF | R37: 6.58 | S37: 0.3 | T37: L01, L07 | U37: type=chronology name=Georgetown & Tennallytown line network=Washington, D.C. streetcars operator=Georgetown & Tennallytown Railway start_date=1890 end_date=1960 ref:streetcar_project=L36 ref=30;31 description=Later operators: Washington Traction & Electric; WRECo (fully 1926); Capital Transit; D.C. Transit source=WP; MPD; CRF Dated route relations in this chronology: 1890–1902: 7 ways; operator=Georgetown & Tennallytown Railway; railway:traction=electric 1902–1934: 7 ways; operator=Washington Railway & Electric; railway:traction=electric 1934–1956: 7 ways; operator=Capital Transit; railway:traction=electric 1956–1960: 7 ways; operator=D.C. Transit; railway:traction=electric
A38: L37 | B38: Friendship Heights – Bethesda – Rockville line | C38: Wisconsin & Willard Aves along Old Georgetown Rd to Bethesda (Bethesda Park, 3.75 mi); extended to Rockville | D38: MD | E38: Tennallytown & Rockville RR (1890); Washington & Rockville Railway (1897) | F38: WRECo; Capital Transit | G38: Electric | H38: 1890 | I38: — | J38: — | K38: 1890 | L38: — (bus T6) | M38: Aug 4, 1935 | N38: 1935 | O38: Bus T6 (later Ride-On) | P38: T&R opened July 4, 1891 to Bethesda Park; foreclosed May 1896. W&R incorporated Sept 9, 1897; tracks to Rockville by 1900, Woodlawn Hotel 1904. 24 trips a day in 1929. | Q38: WP; MPD; CRF | R38: 15.49 | S38: 0 | T38: — | U38: type=chronology name=Friendship Heights – Bethesda – Rockville line network=Washington, D.C. streetcars operator=Tennallytown & Rockville RR (1890); Washington & Rockville Railway (1897) start_date=1890 end_date=1935 ref:streetcar_project=L37 description=Later operators: WRECo; Capital Transit source=WP; MPD; CRF Dated route relations in this chronology: 1891–1900: 3 ways; operator=Tennallytown & Rockville RR; railway:traction=electric 1900–1902: 4 ways; operator=Tennallytown & Rockville RR; railway:traction=electric 1902–1934: 4 ways; operator=Washington Railway & Electric; railway:traction=electric 1934–1935: 4 ways; operator=Capital Transit; railway:traction=electric
A39: L38 | B39: Glen Echo Railroad | C39: Wisconsin & Willard Aves west to Conduit Rd (MacArthur Blvd) & Walhonding Rd; extended 1896 to Glen Echo and Cabin John | D39: MD | E39: Glen Echo Railroad (1889); Washington & Glen Echo RR (1896) | F39: Walhonding–Cabin John section absorbed by Washington & Great Falls (1902) | G39: Electric | H39: 1891 | I39: — | J39: — | K39: 1891 | L39: — | M39: Oct 1902 | N39: 1902 | O39: — | P39: Opened June 1891. | Q39: WPMD; MPD | R39: 6.39 | S39: 0.4 | T39: L39 | U39: type=chronology name=Glen Echo Railroad network=Washington, D.C. streetcars operator=Glen Echo Railroad (1889); Washington & Glen Echo RR (1896) start_date=1891 end_date=1902 ref:streetcar_project=L38 description=Later operators: Walhonding–Cabin John section absorbed by Washington & Great Falls (1902) source=WPMD; MPD Dated route relations in this chronology: 1891–1896: 1 ways; operator=Glen Echo Railroad; railway:traction=electric 1896–1902: 9 ways; operator=Glen Echo Railroad; railway:traction=electric
